<?xml version="1.0"?>
<robot name="elac_tester" xmlns:xacro="http://www.ros.org/wiki/xacro">
  <xacro:arg name="initial_position" default="0.0"/>

  <link name="base_link"/>

  <link name="elac_link">
    <inertial>
      <origin xyz="0 0 0.05" rpy="0 0 0"/>
      <mass value="0.1"/>
      <inertia ixx="0.0001" ixy="0.0" ixz="0.0" iyy="0.0001" iyz="0.0" izz="0.0001"/>
    </inertial>
    <visual>
      <origin xyz="0 0 0.05" rpy="0 0 0"/>
      <geometry>
        <box size="0.05 0.05 0.10"/>
      </geometry>
      <material name="elac_blue">
        <color rgba="0.0 0.25 0.8 1.0"/>
      </material>
    </visual>
    <collision>
      <origin xyz="0 0 0.05" rpy="0 0 0"/>
      <geometry>
        <box size="0.05 0.05 0.10"/>
      </geometry>
    </collision>
  </link>

  <joint name="elac_node" type="revolute">
    <parent link="base_link"/>
    <child link="elac_link"/>
    <origin xyz="0 0 0" rpy="0 0 0"/>
    <axis xyz="0 0 1"/>
    <limit lower="-3.14159" upper="3.14159" effort="10.0" velocity="1.0"/>
  </joint>

  <ros2_control name="ElacTesterMockSystem" type="system">
    <hardware>
      <plugin>mock_components/GenericSystem</plugin>
    </hardware>

    <joint name="elac_node">
      <command_interface name="position"/>
      <state_interface name="position">
        <param name="initial_value">$(arg initial_position)</param>
      </state_interface>
    </joint>
  </ros2_control>
</robot>
