<?xml version="1.0" ?>
<!-- =================================================================================== -->
<!-- |    This document was autogenerated by xacro from vhit_robotics_rev_1.urdf.xacro | -->
<!-- |    EDITING THIS FILE BY HAND IS NOT RECOMMENDED                                 | -->
<!-- =================================================================================== -->
<robot name="vhit_robotics_rev_1">
  <!-- Colors -->
  <material name="blue">
    <color rgba="0.231373 0.380392 0.705882 1"/>
  </material>
  <material name="grey">
    <color rgba="0.701961 0.701961 0.701961 1"/>
  </material>
  <material name="light_blue">
    <color rgba="0.32549 0.529412 0.752941 1"/>
  </material>
  <!-- WORLD FRAME -->
  <link name="world"/>
  <!-- BASE LINK -->
  <link name="base">
    <inertial>
      <origin rpy="0 0 0" xyz="0 0 0"/>
      <mass value="1.0"/>
      <inertia ixx="1.0" ixy="0" ixz="0" iyy="1.0" iyz="0" izz="1.0"/>
    </inertial>
    <!-- Part base -->
    <visual>
      <origin rpy="3.14159 0.0135592 -3.14159" xyz="0 -0.0605 0.03"/>
      <geometry>
        <mesh filename="package://vhit_robot_demo/meshes/base.stl"/>
      </geometry>
      <material name="blue"/>
    </visual>
    <collision>
      <origin rpy="3.14159 0.0135592 -3.14159" xyz="0 -0.0605 0.03"/>
      <geometry>
        <mesh filename="package://vhit_robot_demo/meshes/base.stl"/>
      </geometry>
    </collision>
    <!-- Part elac217_f -->
    <visual>
      <origin rpy="-1.5708 -0.0135592 0" xyz="0 -0.0605 0.03"/>
      <geometry>
        <mesh filename="package://vhit_robot_demo/meshes/elac217_f.stl"/>
      </geometry>
      <material name="grey"/>
    </visual>
    <collision>
      <origin rpy="-1.5708 -0.0135592 0" xyz="0 -0.0605 0.03"/>
      <geometry>
        <mesh filename="package://vhit_robot_demo/meshes/elac217_f.stl"/>
      </geometry>
    </collision>
  </link>
  <!-- SHOULDER LINK -->
  <link name="shoulder">
    <inertial>
      <origin rpy="0 0 0" xyz="0 0 0"/>
      <mass value="0.5"/>
      <inertia ixx="1.0" ixy="0" ixz="0" iyy="1.0" iyz="0" izz="1.0"/>
    </inertial>
    <!-- Part elac217_b -->
    <visual>
      <origin rpy="1.5708 1.5708 0" xyz="0 -0.032 -0.056125"/>
      <geometry>
        <mesh filename="package://vhit_robot_demo/meshes/elac217_b.stl"/>
      </geometry>
      <material name="grey"/>
    </visual>
    <collision>
      <origin rpy="1.5708 1.5708 0" xyz="0 -0.032 -0.056125"/>
      <geometry>
        <mesh filename="package://vhit_robot_demo/meshes/elac217_b.stl"/>
      </geometry>
    </collision>
    <!-- Part shoulder -->
    <visual>
      <origin rpy="-1.5708 -0 -0" xyz="0 -0.032 -0.056125"/>
      <geometry>
        <mesh filename="package://vhit_robot_demo/meshes/shoulder.stl"/>
      </geometry>
      <material name="blue"/>
    </visual>
    <collision>
      <origin rpy="-1.5708 -0 -0" xyz="0 -0.032 -0.056125"/>
      <geometry>
        <mesh filename="package://vhit_robot_demo/meshes/shoulder.stl"/>
      </geometry>
    </collision>
  </link>
  <!-- ARM1 LINK -->
  <link name="arm1">
    <inertial>
      <origin rpy="0 0 0" xyz="0.142779 3.59198e-07 -0.0248996"/>
      <mass value="1.88077"/>
      <inertia ixx="0.00149224" ixy="-1.53387e-07" ixz="-0.000665626" iyy="0.0275846" iyz="2.682e-09" izz="0.0281824"/>
    </inertial>
    <!-- Part arm1 -->
    <visual>
      <origin rpy="-1.5708 0 0" xyz="0.178 0 -0"/>
      <geometry>
        <mesh filename="package://vhit_robot_demo/meshes/arm1.stl"/>
      </geometry>
      <material name="blue"/>
    </visual>
    <collision>
      <origin rpy="-1.5708 0 0" xyz="0.178 0 -0"/>
      <geometry>
        <mesh filename="package://vhit_robot_demo/meshes/arm1.stl"/>
      </geometry>
    </collision>
    <!-- Part arm2 -->
    <visual>
      <origin rpy="-1.5708 -0 3.14159" xyz="0.178 0 -0"/>
      <geometry>
        <mesh filename="package://vhit_robot_demo/meshes/arm2.stl"/>
      </geometry>
      <material name="blue"/>
    </visual>
    <collision>
      <origin rpy="-1.5708 -0 3.14159" xyz="0.178 0 -0"/>
      <geometry>
        <mesh filename="package://vhit_robot_demo/meshes/arm2.stl"/>
      </geometry>
    </collision>
  </link>
  <!-- ELAC217_B LINK -->
  <link name="elac217_b">
    <inertial>
      <origin rpy="0 0 0" xyz="0 0 0"/>
      <mass value="0.3"/>
      <inertia ixx="1.0" ixy="0" ixz="0" iyy="1.0" iyz="0" izz="1.0"/>
    </inertial>
    <!-- Part forearm -->
    <visual>
      <origin rpy="1.5708 -0 0" xyz="0.13 0 -0.0125"/>
      <geometry>
        <mesh filename="package://vhit_robot_demo/meshes/forearm.stl"/>
      </geometry>
      <material name="blue"/>
    </visual>
    <collision>
      <origin rpy="1.5708 -0 0" xyz="0.13 0 -0.0125"/>
      <geometry>
        <mesh filename="package://vhit_robot_demo/meshes/forearm.stl"/>
      </geometry>
    </collision>
    <!-- Part elac214_f -->
    <visual>
      <origin rpy="-0 -0 -1.5708" xyz="0.26 0 -0.0125"/>
      <geometry>
        <mesh filename="package://vhit_robot_demo/meshes/elac214_f.stl"/>
      </geometry>
      <material name="grey"/>
    </visual>
    <collision>
      <origin rpy="-0 -0 -1.5708" xyz="0.26 0 -0.0125"/>
      <geometry>
        <mesh filename="package://vhit_robot_demo/meshes/elac214_f.stl"/>
      </geometry>
    </collision>
    <!-- Part elac217_b_2 -->
    <visual>
      <origin rpy="-0 -0 -0" xyz="-0 -0 -0.0125"/>
      <geometry>
        <mesh filename="package://vhit_robot_demo/meshes/elac217_b.stl"/>
      </geometry>
      <material name="grey"/>
    </visual>
    <collision>
      <origin rpy="-0 -0 -0" xyz="-0 -0 -0.0125"/>
      <geometry>
        <mesh filename="package://vhit_robot_demo/meshes/elac217_b.stl"/>
      </geometry>
    </collision>
  </link>
  <!-- WRIST LINK -->
  <link name="wrist">
    <inertial>
      <origin rpy="0 0 0" xyz="0 0 0"/>
      <mass value="0.2"/>
      <inertia ixx="1.0" ixy="0" ixz="0" iyy="1.0" iyz="0" izz="1.0"/>
    </inertial>
    <!-- Part wrist -->
    <visual>
      <origin rpy="-1.5708 -0 0" xyz="0.13 0 -0"/>
      <geometry>
        <mesh filename="package://vhit_robot_demo/meshes/wrist.stl"/>
      </geometry>
      <material name="blue"/>
    </visual>
    <collision>
      <origin rpy="-1.5708 -0 0" xyz="0.13 0 -0"/>
      <geometry>
        <mesh filename="package://vhit_robot_demo/meshes/wrist.stl"/>
      </geometry>
    </collision>
    <!-- Part elac214_f_2 -->
    <visual>
      <origin rpy="1.5708 -0 1.5708" xyz="0.12 0 0.036125"/>
      <geometry>
        <mesh filename="package://vhit_robot_demo/meshes/elac214_f.stl"/>
      </geometry>
      <material name="grey"/>
    </visual>
    <collision>
      <origin rpy="1.5708 -0 1.5708" xyz="0.12 0 0.036125"/>
      <geometry>
        <mesh filename="package://vhit_robot_demo/meshes/elac214_f.stl"/>
      </geometry>
    </collision>
  </link>
  <!-- FLANGE LINK -->
  <link name="flange">
    <inertial>
      <origin rpy="0 0 0" xyz="0 0 0"/>
      <mass value="0.1"/>
      <inertia ixx="1.0" ixy="0" ixz="0" iyy="1.0" iyz="0" izz="1.0"/>
    </inertial>
    <!-- Part flange -->
    <visual>
      <origin rpy="-1.5708 -0 0" xyz="0 -0.03 -0.065125"/>
      <geometry>
        <mesh filename="package://vhit_robot_demo/meshes/flange.stl"/>
      </geometry>
      <material name="light_blue"/>
    </visual>
    <collision>
      <origin rpy="-1.5708 -0 0" xyz="0 -0.03 -0.065125"/>
      <geometry>
        <mesh filename="package://vhit_robot_demo/meshes/flange.stl"/>
      </geometry>
    </collision>
  </link>
  <!-- JOINTS -->
  <!-- World to base fixed joint -->
  <joint name="world_to_base" type="fixed">
    <parent link="world"/>
    <child link="base"/>
    <origin rpy="1.57 0 0" xyz="0 0 0.15"/>
  </joint>
  <joint name="rotbase" type="revolute">
    <origin rpy="1.5708 -1.03756 0" xyz="-0 -0.048 0.03"/>
    <parent link="base"/>
    <child link="shoulder"/>
    <axis xyz="0 0 1"/>
    <limit effort="10" lower="-3.14159" upper="3.14159" velocity="10"/>
  </joint>
  <joint name="shoulder_joint" type="revolute">
    <origin rpy="-1.5708 1.13806 0" xyz="0 -0.0445 -0.056125"/>
    <parent link="shoulder"/>
    <child link="arm1"/>
    <axis xyz="0 0 1"/>
    <limit effort="10" lower="-3.14159" upper="3.14159" velocity="10"/>
  </joint>
  <joint name="elbow" type="revolute">
    <origin rpy="-3.14159 -0 -1.75984" xyz="0.356 -0 -0"/>
    <parent link="arm1"/>
    <child link="elac217_b"/>
    <axis xyz="0 0 1"/>
    <limit effort="10" lower="-3.14159" upper="3.14159" velocity="10"/>
  </joint>
  <joint name="wrist_pitch" type="revolute">
    <origin rpy="-3.14159 -0 -0.569007" xyz="0.26 0 -0.0005"/>
    <parent link="elac217_b"/>
    <child link="wrist"/>
    <axis xyz="0 0 1"/>
    <limit effort="10" lower="-3.14159" upper="3.14159" velocity="10"/>
  </joint>
  <joint name="wrist_roll" type="revolute">
    <origin rpy="1.5708 -1.45886 -1.5708" xyz="0.132 0 0.036125"/>
    <parent link="wrist"/>
    <child link="flange"/>
    <axis xyz="0 0 1"/>
    <limit effort="10" lower="-3.14159" upper="3.14159" velocity="10"/>
  </joint>
  <gazebo>
    <plugin filename="libgz_ros2_control-system.so" name="gz_ros2_control::GazeboSimROS2ControlPlugin">
      <parameters>
        /home/riky/vhit-robot-demo/install/vhit_robot_demo/share/vhit_robot_demo/config/vhit_robotics_rev_1_controllers.yaml
      </parameters>
    </plugin>
  </gazebo>
  <ros2_control name="robot_system" type="system">
    <!-- <hardware>
      <plugin>gz_ros2_control/GazeboSimSystem</plugin>
    </hardware> -->
    <hardware>
      <plugin>mock_components/GenericSystem</plugin>
    </hardware>
    <joint name="rotbase">
      <command_interface name="position">
        <param name="min">-3.14159</param>
        <param name="max">3.14159</param>
      </command_interface>
      <state_interface name="position"/>
    </joint>
    <joint name="shoulder_joint">
      <command_interface name="position">
        <param name="min">-3.14159</param>
        <param name="max">3.14159</param>
      </command_interface>
      <state_interface name="position"/>
    </joint>
    <joint name="elbow">
      <command_interface name="position">
        <param name="min">-3.14159</param>
        <param name="max">3.14159</param>
      </command_interface>
      <state_interface name="position"/>
    </joint>
    <joint name="wrist_pitch">
      <command_interface name="position">
        <param name="min">-3.14159</param>
        <param name="max">3.14159</param>
      </command_interface>
      <state_interface name="position"/>
    </joint>
    <joint name="wrist_roll">
      <command_interface name="position">
        <param name="min">-3.14159</param>
        <param name="max">3.14159</param>
      </command_interface>
      <state_interface name="position"/>
    </joint>
  </ros2_control>
</robot>
